#VRML_SIM R2021b utf8
WorldInfo {
  coordinateSystem "NUE"
  contactProperties [
    ContactProperties {
      coulombFriction [
        0.3
      ]
    }
  ]
}
Viewpoint {
  orientation 0.21292143275450953 0.9132582522520575 0.3473094127248559 4.1449389734886175
  position -8.153151356290483 8.424326353567837 -5.5602396897585855
}
Background {
  skyColor [
    1 1 1
  ]
}
DEF FloorSolid Solid {
  translation 0.08 -0.02 0
  children [
    DEF Floor Shape {
      appearance Appearance {
        material Material {
          diffuseColor 0.666667 0.333333 0
        }
      }
      geometry Box {
        size 5 0.1 5
      }
    }
  ]
  name "solid(1)"
  boundingObject DEF Floor Shape {
    appearance Appearance {
      material Material {
        diffuseColor 0.666667 0.333333 0
      }
    }
    geometry Box {
      size 5 0.1 5
    }
  }
}
DEF Wall1 Solid {
  translation 0.0200006 0.24 2.47
  rotation 0 0 -1 -3.1415853071795863
  children [
    DEF wall01 Shape {
      appearance Appearance {
        material Material {
          diffuseColor 0 0.333333 0
        }
      }
      geometry Box {
        size 5 0.5 0.1
      }
    }
  ]
  boundingObject USE wall01
}
DEF Wall2 Solid {
  translation 0.03 0.27 -2.54
  rotation 0 0 -1 -3.1415853071795863
  children [
    DEF wall02 Shape {
      appearance Appearance {
        material Material {
          diffuseColor 0 0.333333 0
        }
      }
      geometry Box {
        size 5 0.5 0.1
      }
    }
  ]
  boundingObject USE wall02
}
DEF Wall3 Solid {
  translation -2.46 0.25909 -0.00667031
  rotation 0.707103781176975 -3.4206789414236874e-06 0.7071097811751184 3.14159
  children [
    DEF wall03 Shape {
      appearance Appearance {
        material Material {
          diffuseColor 0 0.333333 0
        }
      }
      geometry Box {
        size 5 0.5 0.1
      }
    }
  ]
  boundingObject USE wall03
}
DEF Wall4 Solid {
  translation 2.55 0.249074 -0.0466253
  rotation 3.3259999999422993e-06 0.9999999999826517 4.8615299999156604e-06 -1.5708053071795867
  children [
    DEF wall04 Shape {
      appearance Appearance {
        material Material {
          diffuseColor 0 0.333333 0
        }
      }
      geometry Box {
        size 5 0.5 0.1
      }
    }
  ]
  boundingObject USE wall04
}
DirectionalLight {
  direction 0 -1 -0.4
  castShadows TRUE
}
DEF Cylinder Solid {
  translation 1.58826 0.270958 -0.652944
  rotation -0.08153704166921875 -0.9941903712899327 -0.0702653290764227 0.0456625380304764
  children [
    Shape {
      appearance Appearance {
        material Material {
          diffuseColor 0.333333 0.666667 1
        }
      }
      geometry Cylinder {
        height 0.5
        radius 0.15
        subdivision 24
      }
    }
  ]
  boundingObject Cylinder {
    height 0.5
    radius 0.15
  }
  physics Physics {
    density -1
    mass 7
    centerOfMass [
      0 0 0
    ]
  }
  recognitionColors [
    1 0 0
  ]
}
DEF Sphere Solid {
  translation 1.4413685024817673 0.31430399999999986 -1.9372892686757668
  rotation 0.0809916010455287 -0.5078069051475921 0.8576552382190097 2.869443867443153
  children [
    Shape {
      appearance Appearance {
        material Material {
          diffuseColor 0.333333 1 1
        }
      }
      geometry Sphere {
        radius 0.3
        subdivision 5
      }
    }
  ]
  boundingObject Sphere {
    radius 0.3
    subdivision 5
  }
  physics Physics {
    density -1
    mass 10
    centerOfMass [
      0 0 0
    ]
  }
  recognitionColors [
    1 0 0
  ]
  linearVelocity 8.054910031731222e-08 6.690155814924672e-16 0.004297647501189307
  angularVelocity 0.015116380709343907 2.691596628750314e-07 -2.833203202111553e-07
}
DEF Cone Solid {
  translation 1.7765 0.280351 0.89023
  rotation -0.001031461970427199 -0.9999147431576211 0.013017008190523299 0.2061207123931621
  children [
    Shape {
      appearance Appearance {
        material Material {
          diffuseColor 1 0 1
        }
      }
      geometry Cone {
        bottomRadius 0.1
        height 0.5
      }
    }
  ]
  boundingObject Group {
    children [
      Transform {
        translation 0 0.11 0
        children [
          Cylinder {
            height 0.3
            radius 0.1
          }
        ]
      }
      Transform {
        translation 0 -0.15 0
        children [
          Cylinder {
            height 0.2
            radius 0.15
          }
        ]
      }
    ]
  }
  physics Physics {
    density -1
    mass 4
    centerOfMass [
      0 0 0
    ]
  }
  recognitionColors [
    1 0 0
  ]
}
Robot {
  translation 0.05842931050099609 0.17214265687897398 -0.08137892262428516
  rotation -7.489317480890065e-06 0.9999999999595167 -4.987661752414483e-06 1.9374496568406363
  scale 4 4 4
  children [
    Solid {
      children [
        Shape {
          appearance PBRAppearance {
            baseColor 1 0.333333 0
          }
          geometry Box {
            size 0.03 0.25 0.03
          }
        }
        Camera {
          translation 0.001 0.1 0
          rotation 0 1 0 -3.1415853071795863
          name "CAM"
          fieldOfView 1
          width 640
          height 640
          recognition Recognition {
            frameThickness 3
          }
        }
      ]
      name "solid(4)"
    }
    DistanceSensor {
      translation -0.02 0 0.1
      rotation 0 -1 0 1.87
      children [
        Shape {
          appearance PBRAppearance {
            baseColor 1 0.333333 0
          }
          geometry Box {
            size 0.01 0.01 0.01
          }
        }
      ]
      name "ds_left"
    }
    DistanceSensor {
      translation 0.02 0 0.1
      rotation 0 -1 0 1.27
      children [
        Shape {
          appearance PBRAppearance {
            baseColor 1 0.333333 0
          }
          geometry Box {
            size 0.01 0.01 0.01
          }
        }
      ]
      name "ds_right"
    }
    HingeJoint {
      jointParameters HingeJointParameters {
        position 629.201048293937
        anchor 0.06 0 0.05
      }
      device [
        RotationalMotor {
          name "wheel1"
        }
      ]
      endPoint Solid {
        translation 0.06 0 0.05
        rotation 0.39302327036301454 -0.3927104199508565 0.8314512824063612 1.7535565875738293
        children [
          DEF robot_wheel Shape {
            appearance PBRAppearance {
            }
            geometry Cylinder {
              height 0.02
              radius 0.04
            }
          }
        ]
        name "solid(1)"
        boundingObject USE robot_wheel
        physics Physics {
        }
      }
    }
    HingeJoint {
      jointParameters HingeJointParameters {
        position 315.18165217724027
        anchor -0.06 0 0.05
      }
      device [
        RotationalMotor {
          name "wheel2"
        }
      ]
      endPoint Solid {
        translation -0.06 0 0.05
        rotation 0.4397314493964238 -0.43938141881157977 0.7833136161301191 1.8118530657404066
        children [
          DEF robot_wheel Shape {
            appearance PBRAppearance {
            }
            geometry Cylinder {
              height 0.02
              radius 0.04
            }
          }
        ]
        name "solid(2)"
        boundingObject USE robot_wheel
        physics Physics {
        }
      }
    }
    HingeJoint {
      jointParameters HingeJointParameters {
        position 629.2023523701487
        anchor 0.06 0 -0.05
      }
      device [
        RotationalMotor {
          name "wheel3"
        }
      ]
      endPoint Solid {
        translation 0.06 0 -0.05
        rotation 0.39348181349864503 -0.39316859808161375 0.8310177590932435 1.7540694189061925
        children [
          DEF robot_wheel Shape {
            appearance PBRAppearance {
            }
            geometry Cylinder {
              height 0.02
              radius 0.04
            }
          }
        ]
        name "solid(3)"
        boundingObject USE robot_wheel
        physics Physics {
        }
      }
    }
    HingeJoint {
      jointParameters HingeJointParameters {
        position 315.1827855806221
        anchor -0.06 0 -0.05
      }
      device [
        RotationalMotor {
          name "wheel4"
        }
      ]
      endPoint Solid {
        translation -0.06 0 -0.05
        rotation 0.44008964268492456 -0.43973932697467905 0.782911508865026 1.8123516618715956
        children [
          DEF robot_wheel Shape {
            appearance PBRAppearance {
            }
            geometry Cylinder {
              height 0.02
              radius 0.04
            }
          }
        ]
        boundingObject USE robot_wheel
        physics Physics {
        }
      }
    }
    DEF body Shape {
      appearance PBRAppearance {
        baseColor 0 0 0
        metalness 0
      }
      geometry Box {
        size 0.1 0.05 0.2
      }
    }
  ]
  boundingObject USE body
  physics Physics {
  }
  controller "pycontroller"
  linearVelocity 0.1493657701525053 5.11109643585835e-08 -0.05735748286848935
  angularVelocity 8.656413176216414e-06 -5.183073192298454e-06 -3.74318861964524e-06
}
